Workbook

Sheet BOM
A1: Reference | B1: Value | C1: Qty | D1: Supplier | E1: Part number | F1: Column1
A2: Q111,Q113,Q121,Q123,Q132,Q142 | B2: BC557 | C2: 6 | D2: Cypax | E2: 01.020.0557 | F2: 1
A3: Q112,Q122,Q131,Q141,Q210,Q220,Q230,Q240 | B3: BC547 | C3: 8 | D3: Farnell | E3: 1574381 | F3: 2
A4: U901 | B4: L78L05 | C4: 1 | D4: RS | E4: 885-5423 | F4: 3
A5: C110,C120 | B5: 2.2uF | C5: 2 | D5: Farnell | E5: 8766797 | F5: 4
A6: J410 | B6: Conn_01x06_Pin | C6: 1 | D6: - | E6: - | F6: =IFERROR(BOM[[#This Row],[Qty]]*15,0) -> 15
A7: F1 | B7: Fuse | C7: 1 | D7: Cypax | E7: 18.099.0078.10 | F7: =IFERROR(BOM[[#This Row],[Qty]]*15,0) -> 15
A8: R403 | B8: 100R | C8: 1 | D8: Cypax | E8: 05.000.0510 | F8: =IFERROR(BOM[[#This Row],[Qty]]*15,0) -> 15
A9: R901 | B9: 390 | C9: 1 | D9: Cypax | E9: 05.000.0339 | F9: =IFERROR(BOM[[#This Row],[Qty]]*15,0) -> 15
A10: R902 | B10: 68R | C10: 1 | D10: Cypax | E10: 05.000.0268 | F10: =IFERROR(BOM[[#This Row],[Qty]]*15,0) -> 15
A11: C900 | B11: 220uF | C11: 1 | D11: Farnell | E11: 3254121 | F11: =IFERROR(BOM[[#This Row],[Qty]]*15,0) -> 15
A12: DS300 | B12: WC1602A | C12: 1 | D12: Farnell | E12: 1218634 | F12: =IFERROR(BOM[[#This Row],[Qty]]*15,0) -> 15
A13: J411 | B13: USB_B | C13: 1 | D13: Farnell | E13: 1076666 | F13: =IFERROR(BOM[[#This Row],[Qty]]*15,0) -> 15
A14: U410 | B14: MCP2221AxP | C14: 1 | D14: Farnell | E14: 2678459 | F14: =IFERROR(BOM[[#This Row],[Qty]]*15,0) -> 15
A15: U902 | B15: HCPL7510 | C15: 1 | D15: Farnell | E15: 1085055 | F15: =IFERROR(BOM[[#This Row],[Qty]]*15,0) -> 15
A16: J1,J4,J5,J6 | B16: Conn_01x02_Socket | C16: 1 | D16: RS | E16: 252-5139 | F16: =IFERROR(BOM[[#This Row],[Qty]]*15,0) -> 15
A17: J400 | B17: Conn_01x05_Socket | C17: 1 | D17: RS | E17: 233-9362 | F17: =IFERROR(BOM[[#This Row],[Qty]]*15,0) -> 15
... A25: U900 | B25: LM317 | C25: 1 | D25: RS | E25: 168-8786 | F25: =IFERROR(BOM[[#This Row],[Qty]]*15,0) -> 15
B26: Conn_01x04_Plug | C26: 1 | D26: RS | E26: 252-5150 | F26: =IFERROR(BOM[[#This Row],[Qty]]*15,0) -> 15
B27: Conn_01x06_Socket | C27: 1 | D27: RS | E27: 252-5144 | F27: =IFERROR(BOM[[#This Row],[Qty]]*15,0) -> 15
B28: Dil socket 28 pin | C28: 1 | D28: RS | E28: 183-1570 | F28: =IFERROR(BOM[[#This Row],[Qty]]*15,0) -> 15
B29: Dil socket 16 pin | C29: 1 | D29: RS | E29: 183-1561 | F29: =IFERROR(BOM[[#This Row],[Qty]]*15,0) -> 15
B30: Dil socket 14 pin | C30: 1 | D30: RS | E30: 183-1562 | F30: =IFERROR(BOM[[#This Row],[Qty]]*15,0) -> 15
B31: Dil socket 8 pin | C31: 1 | D31: RS | E31: 183-1560 | F31: =IFERROR(BOM[[#This Row],[Qty]]*15,0) -> 15
A32: R111,R121 | B32: 47k | C32: 2 | D32: Cypax | E32: 05.000.0547 | F32: =IFERROR(BOM[[#This Row],[Qty]]*15,0) -> 30
A33: R131,R141 | B33: 270k | C33: 2 | D33: Cypax | E33: 05.000.0627 | F33: =IFERROR(BOM[[#This Row],[Qty]]*15,0) -> 30
A34: R900,R903 | B34: 3k3 | C34: 2 | D34: Cypax | E34: 05.000.0433 | F34: =IFERROR(BOM[[#This Row],[Qty]]*15,0) -> 30
A35: C901,C902 | B35: 10uF | C35: 2 | D35: Farnell | E35: 2901339 | F35: =IFERROR(BOM[[#This Row],[Qty]]*15,0) -> 30
B36: Conn_01x02_Plug | C36: 2 | D36: RS | E36: 252-5148 | F36: =IFERROR(BOM[[#This Row],[Qty]]*15,0) -> 30
A37: R110,R120,R130,R140 | B37: 10R | C37: 4 | D37: Cypax | E37: 05.000.0210 | F37: =IFERROR(BOM[[#This Row],[Qty]]*15,0) -> 60
A38: R112,R122,R132,R142 | B38: 150R | C38: 4 | D38: Cypax | E38: 05.000.0315 | F38: =IFERROR(BOM[[#This Row],[Qty]]*15,0) -> 60
A39: R210,R220,R230,R240 | B39: 180 | C39: 4 | D39: Cypax | E39: 05.000.0318 | F39: =IFERROR(BOM[[#This Row],[Qty]]*15,0) -> 60
A40: Q110,Q120,Q130,Q140 | B40: IRLZ44N | C40: 4 | D40: Farnell | E40: 8651418 | F40: =IFERROR(BOM[[#This Row],[Qty]]*15,0) -> 60
A41: U210,U220,U230,U240 | B41: 4N35 | C41: 4 | D41: Farnell | E41: 1021351 | F41: =IFERROR(BOM[[#This Row],[Qty]]*15,0) -> 60
B42: Dil socket 6 pin | C42: 4 | D42: RS | E42: 702-0657 | F42: =IFERROR(BOM[[#This Row],[Qty]]*15,0) -> 60
A43: R211,R221,R231,R241,R251,R300,R310,R311,R312,R400,R401,R402,R410 | B43: 10k | C43: 13 | D43: Cypax | E43: 05.000.0510 | F43: =IFERROR(BOM[[#This Row],[Qty]]*15,0) -> 195
A44: R113,R114,R123,R124,R133,R143,R212,R222,R232,R242,R250,R313,R314,R315 | B44: 1k | C44: 14 | D44: Cypax | E44: 05.000.0410 | F44: =IFERROR(BOM[[#This Row],[Qty]]*15,0) -> 210
A45: Q112,Q122,Q131,Q141,Q210,Q220,Q230,Q240 | B45: BC547 | C45: 0 | D45: Cypax | E45: 01.020.0547
A46: U400 | B46: PIC18F27Q43-xSP | C46: 0 | D46: Farnell | E46: 3052751
A47: U410 | B47: MCP2221AxP | C47: 0 | D47: RS | E47: 171-7757
...

Sheet Sheet1
A1: =BOM!A18 -> J401 | C1: =BOM!B18 -> Conn_01x04_Socket | D1: =BOM!A19 -> L410 | F1: =BOM!B19 -> Ferrite_Small | G1: =BOM!A20 -> R000 | I1: =BOM!B20 -> 0R20
A2: =BOM!D18 -> RS | B2: =BOM!E18 -> 233-9354 | D2: =BOM!D19 -> RS | E2: =BOM!E19 -> 467-3315 | G2: =BOM!D20 -> RS | H2: =BOM!E20 -> 846-9836
A3: =BOM!A22 -> SW310 | C3: =BOM!B22 -> RotaryEncoder_Switch_MP | D3: =BOM!A23 -> U300 | F3: =BOM!B23 -> 74AHC595 | G3: =BOM!A25 -> U900 | I3: =BOM!B51 -> 10nF
A4: =BOM!D22 -> RS | B4: =BOM!E22 -> 781-6830 | D4: =BOM!D23 -> RS | E4: =BOM!E23 -> 100-0763 | G4: =BOM!D51 -> RS | H4: =BOM!E51 -> 134-5708
A5: =BOM!A26 | C5: =BOM!B47 -> MCP2221AxP | D5: U902 | F5: =BOM!B50 -> 470nF | G5: =BOM!A27 | I5: =BOM!B49 -> 100nF
A6: =BOM!D47 -> RS | B6: =BOM!E47 -> 171-7757 | D6: =BOM!D50 -> RS | E6: =BOM!E50 -> 172-5820 | G6: =BOM!D49 -> RS | H6: =BOM!E49 -> 135-8304
A7: =BOM!A39 -> R210,R220,R230,R240 | C7: =BOM!B48 -> 1N4148 | D7: =BOM!A42 | F7: =BOM!B42 -> Dil socket 6 pin | G7: =BOM!A43 -> R211,R221,R231,R241,R251,R300,R310,R311,R312,R400,R401,R402,R410 | I7: =BOM!B43 -> 10k
A8: =BOM!D48 -> Cypax | B8: =BOM!E48 -> 00.001.4148 | D8: =BOM!D42 -> RS | E8: =BOM!E42 -> 702-0657 | G8: =BOM!D43 -> Cypax | H8: =BOM!E43 -> 05.000.0510
A9: =BOM!A35 -> C901,C902 | C9: Ferrite Small | D9: =BOM!A38 -> R112,R122,R132,R142 | F9: Rotary Encoder | G9: =BOM!B46 -> PIC18F27Q43-xSP
A10: =BOM!D34 -> Cypax | B10: =BOM!E34 -> 05.000.0433 | D10: =BOM!D38 -> Cypax | E10: =BOM!E38 -> 05.000.0315 | G10: =BOM!D46 -> Farnell | H10: =BOM!E46 -> 3052751
A11: =BOM!B32 -> 47k | D11: =BOM!A33 -> R131,R141 | F11: Conn_01x05 Socket | G11: =BOM!A34 -> R900,R903 | I11: Conn_01x04 Socket
A12: =BOM!D32 -> Cypax | B12: =BOM!E32 -> 05.000.0547 | D12: =BOM!D33 -> Cypax | E12: =BOM!E33 -> 05.000.0627 | G12: =BOM!D34 -> Cypax | H12: =BOM!E34 -> 05.000.0433
